{
 "cells": [
  {
   "cell_type": "code",
   "execution_count": 4,
   "id": "1a6fc013-4dfd-4973-978e-f993d90ec782",
   "metadata": {},
   "outputs": [],
   "source": [
    "import keras_tuner\n",
    "from tensorflow import keras\n",
    "from tensorflow.keras.models import load_model\n",
    "from tensorflow.keras.preprocessing.image import ImageDataGenerator\n",
    "import numpy as np\n",
    "import time\n",
    "import os"
   ]
  },
  {
   "cell_type": "code",
   "execution_count": 5,
   "id": "135af8bc-9237-407b-845a-74540d0290a1",
   "metadata": {},
   "outputs": [],
   "source": [
    "def Mobilenet_v2(input_size,weights,Dropout_rate,Trainable,alpha = 0.35):\n",
    "    base_model = keras.applications.MobileNetV2(\n",
    "        input_shape=(input_size, input_size, 3),\n",
    "        alpha=alpha,\n",
    "        weights=weights,\n",
    "        include_top=False\n",
    "    )\n",
    "    inputs = keras.Input(shape=(input_size, input_size,3))\n",
    "\n",
    "    scale_layer = keras.layers.Rescaling(scale=1 / 127.5, offset=-1)\n",
    "    x = scale_layer(inputs)\n",
    "    x = base_model(x, training=False)\n",
    "    if Trainable:\n",
    "        base_model.trainable =True\n",
    "    else:\n",
    "        base_model.trainable = False\n",
    "        print(\"特征层已冻结\")\n",
    "    x = keras.layers.GlobalAveragePooling2D()(x)\n",
    "    x = keras.layers.Dropout(Dropout_rate, name='Dropout')(x)\n",
    "    outputs = keras.layers.Dense(15, activation='softmax')(x)\n",
    "    model = keras.Model(inputs, outputs)\n",
    "    return model\n",
    "\n",
    "\n",
    "class HyperMobilenet_v2(keras_tuner.HyperModel):\n",
    "    def __init__(self,input_size,batch_size,train_root):\n",
    "        super(keras_tuner.HyperModel, self).__init__()\n",
    "        self.input_size = input_size\n",
    "        self.batch_size = batch_size\n",
    "        self.train_root = train_root\n",
    "    def model(self,Dropout_rate,lr):\n",
    "        model = Mobilenet_v2(\n",
    "            input_size=self.input_size,\n",
    "            weights='imagenet',\n",
    "            Dropout_rate=Dropout_rate,\n",
    "            Trainable=True\n",
    "        )\n",
    "        model.compile(optimizer=keras.optimizers.Adam(learning_rate=lr),\n",
    "                    loss=keras.losses.CategoricalCrossentropy(),\n",
    "                    metrics=[\"accuracy\"])\n",
    "        return model\n",
    "    def build(self, hp):\n",
    "        lr = hp.Float(\"lr\",min_value=1e-5,max_value=1e-3,sampling=\"log\")\n",
    "        Dropout_rate = hp.Choice(\"Dropout_rate\",values =[0.1,0.2,0.3,0.4,0.5,0.6])\n",
    "        return self.model(Dropout_rate,lr) \n",
    "    \n",
    "    def dataset(self, hp):\n",
    "\n",
    "        train_root = self.train_root\n",
    "\n",
    "        zoom_range = hp.Float(\"zoom_range\",min_value=0.1,max_value=0.3,sampling=\"linear\")\n",
    "        # channel_shift_range = hp.Int(\"channel_shift_range\",min_value=0,max_value=30,step=10)\n",
    "\n",
    "        train_generator = ImageDataGenerator(rotation_range=360,\n",
    "                                            zoom_range =zoom_range,\n",
    "                                            horizontal_flip = True,\n",
    "                                            validation_split =0.2,\n",
    "                                            channel_shift_range =channel_shift_range\n",
    "                                            )\n",
    "        train_dataset = train_generator.flow_from_directory(batch_size=self.batch_size,\n",
    "                                                            directory=train_root,\n",
    "                                                            shuffle=True,\n",
    "                                                            target_size=(self.input_size,self.input_size),\n",
    "                                                            subset='training')\n",
    "        valid_dataset = train_generator.flow_from_directory(batch_size=self.batch_size,\n",
    "                                                            directory=train_root,\n",
    "                                                            shuffle=True,\n",
    "                                                            target_size=(self.input_size,self.input_size),\n",
    "                                                            subset='validation')\n",
    "        return train_dataset,valid_dataset\n",
    "\n",
    "    def fit(self, hp, model,**kwargs):\n",
    "        \n",
    "        train_dataset,valid_dataset = self.dataset(hp)\n",
    "\n",
    "        return model.fit(\n",
    "            train_dataset,\n",
    "            validation_data=valid_dataset,\n",
    "            **kwargs\n",
    "        ) "
   ]
  },
  {
   "cell_type": "code",
   "execution_count": 6,
   "id": "b04a7be0-aeae-4816-8eba-c6882086910e",
   "metadata": {},
   "outputs": [
    {
     "name": "stdout",
     "output_type": "stream",
     "text": [
      "Trial 2 Complete [00h 00m 08s]\n",
      "\n",
      "Best val_accuracy So Far: None\n",
      "Total elapsed time: 00h 00m 16s\n",
      "\n",
      "Search: Running Trial #3\n",
      "\n",
      "Value             |Best Value So Far |Hyperparameter\n",
      "3.2437e-05        |0.00025926        |lr\n",
      "0.2               |0.6               |Dropout_rate\n",
      "0.16549           |0.1               |zoom_range\n",
      "30                |0                 |channel_shift_range\n",
      "\n"
     ]
    },
    {
     "name": "stderr",
     "output_type": "stream",
     "text": [
      "2024-08-14 02:39:24.550244: W tensorflow/core/framework/op_kernel.cc:1733] INVALID_ARGUMENT: ValueError: Could not find callback with key=pyfunc_14 in the registry.\n",
      "Traceback (most recent call last):\n",
      "\n",
      "  File \"/root/miniconda3/lib/python3.8/site-packages/tensorflow/python/ops/script_ops.py\", line 258, in __call__\n",
      "    raise ValueError(f\"Could not find callback with key={token} in the \"\n",
      "\n",
      "ValueError: Could not find callback with key=pyfunc_14 in the registry.\n",
      "\n",
      "\n",
      "2024-08-14 02:39:24.550351: W tensorflow/core/kernels/data/generator_dataset_op.cc:108] Error occurred when finalizing GeneratorDataset iterator: INVALID_ARGUMENT: ValueError: Could not find callback with key=pyfunc_14 in the registry.\n",
      "Traceback (most recent call last):\n",
      "\n",
      "  File \"/root/miniconda3/lib/python3.8/site-packages/tensorflow/python/ops/script_ops.py\", line 258, in __call__\n",
      "    raise ValueError(f\"Could not find callback with key={token} in the \"\n",
      "\n",
      "ValueError: Could not find callback with key=pyfunc_14 in the registry.\n",
      "\n",
      "\n",
      "\t [[{{node PyFunc}}]]\n"
     ]
    },
    {
     "name": "stdout",
     "output_type": "stream",
     "text": [
      "Found 64712 images belonging to 15 classes.\n",
      "Found 16171 images belonging to 15 classes.\n",
      "Epoch 1/10\n"
     ]
    },
    {
     "name": "stderr",
     "output_type": "stream",
     "text": [
      "2024-08-14 02:39:32.491937: E tensorflow/stream_executor/cuda/cuda_blas.cc:232] failed to create cublas handle: CUBLAS_STATUS_NOT_INITIALIZED\n",
      "2024-08-14 02:39:32.491965: E tensorflow/stream_executor/cuda/cuda_blas.cc:234] Failure to initialize cublas may be due to OOM (cublas needs some free memory when you initialize it, and your deep-learning framework may have preallocated more than its fair share), or may be because this binary was not built with support for the GPU in your machine.\n",
      "2024-08-14 02:39:32.492047: W tensorflow/core/framework/op_kernel.cc:1745] OP_REQUIRES failed at conv_ops.cc:1120 : NOT_FOUND: No algorithm worked!  Error messages:\n",
      "  Profiling failure on CUDNN engine 1#TC: UNKNOWN: CUDNN_STATUS_EXECUTION_FAILED\n",
      "in tensorflow/stream_executor/cuda/cuda_dnn.cc(4023): 'cudnnConvolutionForward( cudnn.handle(), alpha, input_nd_.handle(), input_data.opaque(), filter_.handle(), filter_data.opaque(), conv_.handle(), ToConvForwardAlgo(algo), scratch_memory.opaque(), scratch_memory.size(), beta, output_nd_.handle(), output_data.opaque())'\n",
      "  Profiling failure on CUDNN engine 1: UNKNOWN: CUDNN_STATUS_EXECUTION_FAILED\n",
      "in tensorflow/stream_executor/cuda/cuda_dnn.cc(4023): 'cudnnConvolutionForward( cudnn.handle(), alpha, input_nd_.handle(), input_data.opaque(), filter_.handle(), filter_data.opaque(), conv_.handle(), ToConvForwardAlgo(algo), scratch_memory.opaque(), scratch_memory.size(), beta, output_nd_.handle(), output_data.opaque())'\n",
      "  Profiling failure on CUDNN engine 0#TC: UNKNOWN: CUDNN_STATUS_EXECUTION_FAILED\n",
      "in tensorflow/stream_executor/cuda/cuda_dnn.cc(4023): 'cudnnConvolutionForward( cudnn.handle(), alpha, input_nd_.handle(), input_data.opaque(), filter_.handle(), filter_data.opaque(), conv_.handle(), ToConvForwardAlgo(algo), scratch_memory.opaque(), scratch_memory.size(), beta, output_nd_.handle(), output_data.opaque())'\n",
      "  Profiling failure on CUDNN engine 0: UNKNOWN: CUDNN_STATUS_EXECUTION_FAILED\n",
      "in tensorflow/stream_executor/cuda/cuda_dnn.cc(4023): 'cudnnConvolutionForward( cudnn.handle(), alpha, input_nd_.handle(), input_data.opaque(), filter_.handle(), filter_data.opaque(), conv_.handle(), ToConvForwardAlgo(algo), scratch_memory.opaque(), scratch_memory.size(), beta, output_nd_.handle(), output_data.opaque())'\n",
      "  Profiling failure on CUDNN engine 2#TC: RESOURCE_EXHAUSTED: Out of memory while trying to allocate 73400320 bytes.\n",
      "  Profiling failure on CUDNN engine 2: RESOURCE_EXHAUSTED: Out of memory while trying to allocate 73400320 bytes.\n",
      "  Profiling failure on CUDNN engine 5#TC: RESOURCE_EXHAUSTED: Out of memory while trying to allocate 38154240 bytes.\n",
      "  Profiling failure on CUDNN engine 5: RESOURCE_EXHAUSTED: Out of memory while trying to allocate 38154240 bytes.\n",
      "Traceback (most recent call last):\n",
      "  File \"/root/miniconda3/lib/python3.8/site-packages/keras_tuner/src/engine/base_tuner.py\", line 274, in _try_run_and_update_trial\n",
      "    self._run_and_update_trial(trial, *fit_args, **fit_kwargs)\n",
      "  File \"/root/miniconda3/lib/python3.8/site-packages/keras_tuner/src/engine/base_tuner.py\", line 239, in _run_and_update_trial\n",
      "    results = self.run_trial(trial, *fit_args, **fit_kwargs)\n",
      "  File \"/root/miniconda3/lib/python3.8/site-packages/keras_tuner/src/engine/tuner.py\", line 314, in run_trial\n",
      "    obj_value = self._build_and_fit_model(trial, *args, **copied_kwargs)\n",
      "  File \"/root/miniconda3/lib/python3.8/site-packages/keras_tuner/src/engine/tuner.py\", line 233, in _build_and_fit_model\n",
      "    results = self.hypermodel.fit(hp, model, *args, **kwargs)\n",
      "  File \"/tmp/ipykernel_20631/355277094.py\", line 76, in fit\n",
      "    return model.fit(\n",
      "  File \"/root/miniconda3/lib/python3.8/site-packages/keras/utils/traceback_utils.py\", line 67, in error_handler\n",
      "    raise e.with_traceback(filtered_tb) from None\n",
      "  File \"/root/miniconda3/lib/python3.8/site-packages/tensorflow/python/eager/execute.py\", line 54, in quick_execute\n",
      "    tensors = pywrap_tfe.TFE_Py_Execute(ctx._handle, device_name, op_name,\n",
      "tensorflow.python.framework.errors_impl.NotFoundError: Graph execution error:\n",
      "\n",
      "Detected at node 'model/mobilenetv2_0.35_128/Conv1/Conv2D' defined at (most recent call last):\n",
      "    File \"/root/miniconda3/lib/python3.8/runpy.py\", line 194, in _run_module_as_main\n",
      "      return _run_code(code, main_globals, None,\n",
      "    File \"/root/miniconda3/lib/python3.8/runpy.py\", line 87, in _run_code\n",
      "      exec(code, run_globals)\n",
      "    File \"/root/miniconda3/lib/python3.8/site-packages/ipykernel_launcher.py\", line 17, in <module>\n",
      "      app.launch_new_instance()\n",
      "    File \"/root/miniconda3/lib/python3.8/site-packages/traitlets/config/application.py\", line 976, in launch_instance\n",
      "      app.start()\n",
      "    File \"/root/miniconda3/lib/python3.8/site-packages/ipykernel/kernelapp.py\", line 712, in start\n",
      "      self.io_loop.start()\n",
      "    File \"/root/miniconda3/lib/python3.8/site-packages/tornado/platform/asyncio.py\", line 199, in start\n",
      "      self.asyncio_loop.run_forever()\n",
      "    File \"/root/miniconda3/lib/python3.8/asyncio/base_events.py\", line 570, in run_forever\n",
      "      self._run_once()\n",
      "    File \"/root/miniconda3/lib/python3.8/asyncio/base_events.py\", line 1859, in _run_once\n",
      "      handle._run()\n",
      "    File \"/root/miniconda3/lib/python3.8/asyncio/events.py\", line 81, in _run\n",
      "      self._context.run(self._callback, *self._args)\n",
      "    File \"/root/miniconda3/lib/python3.8/site-packages/ipykernel/kernelbase.py\", line 510, in dispatch_queue\n",
      "      await self.process_one()\n",
      "    File \"/root/miniconda3/lib/python3.8/site-packages/ipykernel/kernelbase.py\", line 499, in process_one\n",
      "      await dispatch(*args)\n",
      "    File \"/root/miniconda3/lib/python3.8/site-packages/ipykernel/kernelbase.py\", line 406, in dispatch_shell\n",
      "      await result\n",
      "    File \"/root/miniconda3/lib/python3.8/site-packages/ipykernel/kernelbase.py\", line 730, in execute_request\n",
      "      reply_content = await reply_content\n",
      "    File \"/root/miniconda3/lib/python3.8/site-packages/ipykernel/ipkernel.py\", line 383, in do_execute\n",
      "      res = shell.run_cell(\n",
      "    File \"/root/miniconda3/lib/python3.8/site-packages/ipykernel/zmqshell.py\", line 528, in run_cell\n",
      "      return super().run_cell(*args, **kwargs)\n",
      "    File \"/root/miniconda3/lib/python3.8/site-packages/IPython/core/interactiveshell.py\", line 2880, in run_cell\n",
      "      result = self._run_cell(\n",
      "    File \"/root/miniconda3/lib/python3.8/site-packages/IPython/core/interactiveshell.py\", line 2935, in _run_cell\n",
      "      return runner(coro)\n",
      "    File \"/root/miniconda3/lib/python3.8/site-packages/IPython/core/async_helpers.py\", line 129, in _pseudo_sync_runner\n",
      "      coro.send(None)\n",
      "    File \"/root/miniconda3/lib/python3.8/site-packages/IPython/core/interactiveshell.py\", line 3134, in run_cell_async\n",
      "      has_raised = await self.run_ast_nodes(code_ast.body, cell_name,\n",
      "    File \"/root/miniconda3/lib/python3.8/site-packages/IPython/core/interactiveshell.py\", line 3337, in run_ast_nodes\n",
      "      if await self.run_code(code, result, async_=asy):\n",
      "    File \"/root/miniconda3/lib/python3.8/site-packages/IPython/core/interactiveshell.py\", line 3397, in run_code\n",
      "      exec(code_obj, self.user_global_ns, self.user_ns)\n",
      "    File \"/tmp/ipykernel_20631/2539944366.py\", line 9, in <cell line: 9>\n",
      "      tuner.search(epochs=10,workers=8)\n",
      "    File \"/root/miniconda3/lib/python3.8/site-packages/keras_tuner/src/engine/base_tuner.py\", line 234, in search\n",
      "      self._try_run_and_update_trial(trial, *fit_args, **fit_kwargs)\n",
      "    File \"/root/miniconda3/lib/python3.8/site-packages/keras_tuner/src/engine/base_tuner.py\", line 274, in _try_run_and_update_trial\n",
      "      self._run_and_update_trial(trial, *fit_args, **fit_kwargs)\n",
      "    File \"/root/miniconda3/lib/python3.8/site-packages/keras_tuner/src/engine/base_tuner.py\", line 239, in _run_and_update_trial\n",
      "      results = self.run_trial(trial, *fit_args, **fit_kwargs)\n",
      "    File \"/root/miniconda3/lib/python3.8/site-packages/keras_tuner/src/engine/tuner.py\", line 314, in run_trial\n",
      "      obj_value = self._build_and_fit_model(trial, *args, **copied_kwargs)\n",
      "    File \"/root/miniconda3/lib/python3.8/site-packages/keras_tuner/src/engine/tuner.py\", line 233, in _build_and_fit_model\n",
      "      results = self.hypermodel.fit(hp, model, *args, **kwargs)\n",
      "    File \"/tmp/ipykernel_20631/355277094.py\", line 76, in fit\n",
      "      return model.fit(\n",
      "    File \"/root/miniconda3/lib/python3.8/site-packages/keras/utils/traceback_utils.py\", line 64, in error_handler\n",
      "      return fn(*args, **kwargs)\n",
      "    File \"/root/miniconda3/lib/python3.8/site-packages/keras/engine/training.py\", line 1409, in fit\n",
      "      tmp_logs = self.train_function(iterator)\n",
      "    File \"/root/miniconda3/lib/python3.8/site-packages/keras/engine/training.py\", line 1051, in train_function\n",
      "      return step_function(self, iterator)\n",
      "    File \"/root/miniconda3/lib/python3.8/site-packages/keras/engine/training.py\", line 1040, in step_function\n",
      "      outputs = model.distribute_strategy.run(run_step, args=(data,))\n",
      "    File \"/root/miniconda3/lib/python3.8/site-packages/keras/engine/training.py\", line 1030, in run_step\n",
      "      outputs = model.train_step(data)\n",
      "    File \"/root/miniconda3/lib/python3.8/site-packages/keras/engine/training.py\", line 889, in train_step\n",
      "      y_pred = self(x, training=True)\n",
      "    File \"/root/miniconda3/lib/python3.8/site-packages/keras/utils/traceback_utils.py\", line 64, in error_handler\n",
      "      return fn(*args, **kwargs)\n",
      "    File \"/root/miniconda3/lib/python3.8/site-packages/keras/engine/training.py\", line 490, in __call__\n",
      "      return super().__call__(*args, **kwargs)\n",
      "    File \"/root/miniconda3/lib/python3.8/site-packages/keras/utils/traceback_utils.py\", line 64, in error_handler\n",
      "      return fn(*args, **kwargs)\n",
      "    File \"/root/miniconda3/lib/python3.8/site-packages/keras/engine/base_layer.py\", line 1014, in __call__\n",
      "      outputs = call_fn(inputs, *args, **kwargs)\n",
      "    File \"/root/miniconda3/lib/python3.8/site-packages/keras/utils/traceback_utils.py\", line 92, in error_handler\n",
      "      return fn(*args, **kwargs)\n",
      "    File \"/root/miniconda3/lib/python3.8/site-packages/keras/engine/functional.py\", line 458, in call\n",
      "      return self._run_internal_graph(\n",
      "    File \"/root/miniconda3/lib/python3.8/site-packages/keras/engine/functional.py\", line 596, in _run_internal_graph\n",
      "      outputs = node.layer(*args, **kwargs)\n",
      "    File \"/root/miniconda3/lib/python3.8/site-packages/keras/utils/traceback_utils.py\", line 64, in error_handler\n",
      "      return fn(*args, **kwargs)\n",
      "    File \"/root/miniconda3/lib/python3.8/site-packages/keras/engine/training.py\", line 490, in __call__\n",
      "      return super().__call__(*args, **kwargs)\n",
      "    File \"/root/miniconda3/lib/python3.8/site-packages/keras/utils/traceback_utils.py\", line 64, in error_handler\n",
      "      return fn(*args, **kwargs)\n",
      "    File \"/root/miniconda3/lib/python3.8/site-packages/keras/engine/base_layer.py\", line 1014, in __call__\n",
      "      outputs = call_fn(inputs, *args, **kwargs)\n",
      "    File \"/root/miniconda3/lib/python3.8/site-packages/keras/utils/traceback_utils.py\", line 92, in error_handler\n",
      "      return fn(*args, **kwargs)\n",
      "    File \"/root/miniconda3/lib/python3.8/site-packages/keras/engine/functional.py\", line 458, in call\n",
      "      return self._run_internal_graph(\n",
      "    File \"/root/miniconda3/lib/python3.8/site-packages/keras/engine/functional.py\", line 596, in _run_internal_graph\n",
      "      outputs = node.layer(*args, **kwargs)\n",
      "    File \"/root/miniconda3/lib/python3.8/site-packages/keras/utils/traceback_utils.py\", line 64, in error_handler\n",
      "      return fn(*args, **kwargs)\n",
      "    File \"/root/miniconda3/lib/python3.8/site-packages/keras/engine/base_layer.py\", line 1014, in __call__\n",
      "      outputs = call_fn(inputs, *args, **kwargs)\n",
      "    File \"/root/miniconda3/lib/python3.8/site-packages/keras/utils/traceback_utils.py\", line 92, in error_handler\n",
      "      return fn(*args, **kwargs)\n",
      "    File \"/root/miniconda3/lib/python3.8/site-packages/keras/layers/convolutional/base_conv.py\", line 250, in call\n",
      "      outputs = self.convolution_op(inputs, self.kernel)\n",
      "    File \"/root/miniconda3/lib/python3.8/site-packages/keras/layers/convolutional/base_conv.py\", line 225, in convolution_op\n",
      "      return tf.nn.convolution(\n",
      "Node: 'model/mobilenetv2_0.35_128/Conv1/Conv2D'\n",
      "No algorithm worked!  Error messages:\n",
      "  Profiling failure on CUDNN engine 1#TC: UNKNOWN: CUDNN_STATUS_EXECUTION_FAILED\n",
      "in tensorflow/stream_executor/cuda/cuda_dnn.cc(4023): 'cudnnConvolutionForward( cudnn.handle(), alpha, input_nd_.handle(), input_data.opaque(), filter_.handle(), filter_data.opaque(), conv_.handle(), ToConvForwardAlgo(algo), scratch_memory.opaque(), scratch_memory.size(), beta, output_nd_.handle(), output_data.opaque())'\n",
      "  Profiling failure on CUDNN engine 1: UNKNOWN: CUDNN_STATUS_EXECUTION_FAILED\n",
      "in tensorflow/stream_executor/cuda/cuda_dnn.cc(4023): 'cudnnConvolutionForward( cudnn.handle(), alpha, input_nd_.handle(), input_data.opaque(), filter_.handle(), filter_data.opaque(), conv_.handle(), ToConvForwardAlgo(algo), scratch_memory.opaque(), scratch_memory.size(), beta, output_nd_.handle(), output_data.opaque())'\n",
      "  Profiling failure on CUDNN engine 0#TC: UNKNOWN: CUDNN_STATUS_EXECUTION_FAILED\n",
      "in tensorflow/stream_executor/cuda/cuda_dnn.cc(4023): 'cudnnConvolutionForward( cudnn.handle(), alpha, input_nd_.handle(), input_data.opaque(), filter_.handle(), filter_data.opaque(), conv_.handle(), ToConvForwardAlgo(algo), scratch_memory.opaque(), scratch_memory.size(), beta, output_nd_.handle(), output_data.opaque())'\n",
      "  Profiling failure on CUDNN engine 0: UNKNOWN: CUDNN_STATUS_EXECUTION_FAILED\n",
      "in tensorflow/stream_executor/cuda/cuda_dnn.cc(4023): 'cudnnConvolutionForward( cudnn.handle(), alpha, input_nd_.handle(), input_data.opaque(), filter_.handle(), filter_data.opaque(), conv_.handle(), ToConvForwardAlgo(algo), scratch_memory.opaque(), scratch_memory.size(), beta, output_nd_.handle(), output_data.opaque())'\n",
      "  Profiling failure on CUDNN engine 2#TC: RESOURCE_EXHAUSTED: Out of memory while trying to allocate 73400320 bytes.\n",
      "  Profiling failure on CUDNN engine 2: RESOURCE_EXHAUSTED: Out of memory while trying to allocate 73400320 bytes.\n",
      "  Profiling failure on CUDNN engine 5#TC: RESOURCE_EXHAUSTED: Out of memory while trying to allocate 38154240 bytes.\n",
      "  Profiling failure on CUDNN engine 5: RESOURCE_EXHAUSTED: Out of memory while trying to allocate 38154240 bytes.\n",
      "\t [[{{node model/mobilenetv2_0.35_128/Conv1/Conv2D}}]] [Op:__inference_train_function_79089]\n"
     ]
    },
    {
     "ename": "RuntimeError",
     "evalue": "Number of consecutive failures exceeded the limit of 3.\nTraceback (most recent call last):\n  File \"/root/miniconda3/lib/python3.8/site-packages/keras_tuner/src/engine/base_tuner.py\", line 274, in _try_run_and_update_trial\n    self._run_and_update_trial(trial, *fit_args, **fit_kwargs)\n  File \"/root/miniconda3/lib/python3.8/site-packages/keras_tuner/src/engine/base_tuner.py\", line 239, in _run_and_update_trial\n    results = self.run_trial(trial, *fit_args, **fit_kwargs)\n  File \"/root/miniconda3/lib/python3.8/site-packages/keras_tuner/src/engine/tuner.py\", line 314, in run_trial\n    obj_value = self._build_and_fit_model(trial, *args, **copied_kwargs)\n  File \"/root/miniconda3/lib/python3.8/site-packages/keras_tuner/src/engine/tuner.py\", line 233, in _build_and_fit_model\n    results = self.hypermodel.fit(hp, model, *args, **kwargs)\n  File \"/tmp/ipykernel_20631/355277094.py\", line 76, in fit\n    return model.fit(\n  File \"/root/miniconda3/lib/python3.8/site-packages/keras/utils/traceback_utils.py\", line 67, in error_handler\n    raise e.with_traceback(filtered_tb) from None\n  File \"/root/miniconda3/lib/python3.8/site-packages/tensorflow/python/eager/execute.py\", line 54, in quick_execute\n    tensors = pywrap_tfe.TFE_Py_Execute(ctx._handle, device_name, op_name,\ntensorflow.python.framework.errors_impl.NotFoundError: Graph execution error:\n\nDetected at node 'model/mobilenetv2_0.35_128/Conv1/Conv2D' defined at (most recent call last):\n    File \"/root/miniconda3/lib/python3.8/runpy.py\", line 194, in _run_module_as_main\n      return _run_code(code, main_globals, None,\n    File \"/root/miniconda3/lib/python3.8/runpy.py\", line 87, in _run_code\n      exec(code, run_globals)\n    File \"/root/miniconda3/lib/python3.8/site-packages/ipykernel_launcher.py\", line 17, in <module>\n      app.launch_new_instance()\n    File \"/root/miniconda3/lib/python3.8/site-packages/traitlets/config/application.py\", line 976, in launch_instance\n      app.start()\n    File \"/root/miniconda3/lib/python3.8/site-packages/ipykernel/kernelapp.py\", line 712, in start\n      self.io_loop.start()\n    File \"/root/miniconda3/lib/python3.8/site-packages/tornado/platform/asyncio.py\", line 199, in start\n      self.asyncio_loop.run_forever()\n    File \"/root/miniconda3/lib/python3.8/asyncio/base_events.py\", line 570, in run_forever\n      self._run_once()\n    File \"/root/miniconda3/lib/python3.8/asyncio/base_events.py\", line 1859, in _run_once\n      handle._run()\n    File \"/root/miniconda3/lib/python3.8/asyncio/events.py\", line 81, in _run\n      self._context.run(self._callback, *self._args)\n    File \"/root/miniconda3/lib/python3.8/site-packages/ipykernel/kernelbase.py\", line 510, in dispatch_queue\n      await self.process_one()\n    File \"/root/miniconda3/lib/python3.8/site-packages/ipykernel/kernelbase.py\", line 499, in process_one\n      await dispatch(*args)\n    File \"/root/miniconda3/lib/python3.8/site-packages/ipykernel/kernelbase.py\", line 406, in dispatch_shell\n      await result\n    File \"/root/miniconda3/lib/python3.8/site-packages/ipykernel/kernelbase.py\", line 730, in execute_request\n      reply_content = await reply_content\n    File \"/root/miniconda3/lib/python3.8/site-packages/ipykernel/ipkernel.py\", line 383, in do_execute\n      res = shell.run_cell(\n    File \"/root/miniconda3/lib/python3.8/site-packages/ipykernel/zmqshell.py\", line 528, in run_cell\n      return super().run_cell(*args, **kwargs)\n    File \"/root/miniconda3/lib/python3.8/site-packages/IPython/core/interactiveshell.py\", line 2880, in run_cell\n      result = self._run_cell(\n    File \"/root/miniconda3/lib/python3.8/site-packages/IPython/core/interactiveshell.py\", line 2935, in _run_cell\n      return runner(coro)\n    File \"/root/miniconda3/lib/python3.8/site-packages/IPython/core/async_helpers.py\", line 129, in _pseudo_sync_runner\n      coro.send(None)\n    File \"/root/miniconda3/lib/python3.8/site-packages/IPython/core/interactiveshell.py\", line 3134, in run_cell_async\n      has_raised = await self.run_ast_nodes(code_ast.body, cell_name,\n    File \"/root/miniconda3/lib/python3.8/site-packages/IPython/core/interactiveshell.py\", line 3337, in run_ast_nodes\n      if await self.run_code(code, result, async_=asy):\n    File \"/root/miniconda3/lib/python3.8/site-packages/IPython/core/interactiveshell.py\", line 3397, in run_code\n      exec(code_obj, self.user_global_ns, self.user_ns)\n    File \"/tmp/ipykernel_20631/2539944366.py\", line 9, in <cell line: 9>\n      tuner.search(epochs=10,workers=8)\n    File \"/root/miniconda3/lib/python3.8/site-packages/keras_tuner/src/engine/base_tuner.py\", line 234, in search\n      self._try_run_and_update_trial(trial, *fit_args, **fit_kwargs)\n    File \"/root/miniconda3/lib/python3.8/site-packages/keras_tuner/src/engine/base_tuner.py\", line 274, in _try_run_and_update_trial\n      self._run_and_update_trial(trial, *fit_args, **fit_kwargs)\n    File \"/root/miniconda3/lib/python3.8/site-packages/keras_tuner/src/engine/base_tuner.py\", line 239, in _run_and_update_trial\n      results = self.run_trial(trial, *fit_args, **fit_kwargs)\n    File \"/root/miniconda3/lib/python3.8/site-packages/keras_tuner/src/engine/tuner.py\", line 314, in run_trial\n      obj_value = self._build_and_fit_model(trial, *args, **copied_kwargs)\n    File \"/root/miniconda3/lib/python3.8/site-packages/keras_tuner/src/engine/tuner.py\", line 233, in _build_and_fit_model\n      results = self.hypermodel.fit(hp, model, *args, **kwargs)\n    File \"/tmp/ipykernel_20631/355277094.py\", line 76, in fit\n      return model.fit(\n    File \"/root/miniconda3/lib/python3.8/site-packages/keras/utils/traceback_utils.py\", line 64, in error_handler\n      return fn(*args, **kwargs)\n    File \"/root/miniconda3/lib/python3.8/site-packages/keras/engine/training.py\", line 1409, in fit\n      tmp_logs = self.train_function(iterator)\n    File \"/root/miniconda3/lib/python3.8/site-packages/keras/engine/training.py\", line 1051, in train_function\n      return step_function(self, iterator)\n    File \"/root/miniconda3/lib/python3.8/site-packages/keras/engine/training.py\", line 1040, in step_function\n      outputs = model.distribute_strategy.run(run_step, args=(data,))\n    File \"/root/miniconda3/lib/python3.8/site-packages/keras/engine/training.py\", line 1030, in run_step\n      outputs = model.train_step(data)\n    File \"/root/miniconda3/lib/python3.8/site-packages/keras/engine/training.py\", line 889, in train_step\n      y_pred = self(x, training=True)\n    File \"/root/miniconda3/lib/python3.8/site-packages/keras/utils/traceback_utils.py\", line 64, in error_handler\n      return fn(*args, **kwargs)\n    File \"/root/miniconda3/lib/python3.8/site-packages/keras/engine/training.py\", line 490, in __call__\n      return super().__call__(*args, **kwargs)\n    File \"/root/miniconda3/lib/python3.8/site-packages/keras/utils/traceback_utils.py\", line 64, in error_handler\n      return fn(*args, **kwargs)\n    File \"/root/miniconda3/lib/python3.8/site-packages/keras/engine/base_layer.py\", line 1014, in __call__\n      outputs = call_fn(inputs, *args, **kwargs)\n    File \"/root/miniconda3/lib/python3.8/site-packages/keras/utils/traceback_utils.py\", line 92, in error_handler\n      return fn(*args, **kwargs)\n    File \"/root/miniconda3/lib/python3.8/site-packages/keras/engine/functional.py\", line 458, in call\n      return self._run_internal_graph(\n    File \"/root/miniconda3/lib/python3.8/site-packages/keras/engine/functional.py\", line 596, in _run_internal_graph\n      outputs = node.layer(*args, **kwargs)\n    File \"/root/miniconda3/lib/python3.8/site-packages/keras/utils/traceback_utils.py\", line 64, in error_handler\n      return fn(*args, **kwargs)\n    File \"/root/miniconda3/lib/python3.8/site-packages/keras/engine/training.py\", line 490, in __call__\n      return super().__call__(*args, **kwargs)\n    File \"/root/miniconda3/lib/python3.8/site-packages/keras/utils/traceback_utils.py\", line 64, in error_handler\n      return fn(*args, **kwargs)\n    File \"/root/miniconda3/lib/python3.8/site-packages/keras/engine/base_layer.py\", line 1014, in __call__\n      outputs = call_fn(inputs, *args, **kwargs)\n    File \"/root/miniconda3/lib/python3.8/site-packages/keras/utils/traceback_utils.py\", line 92, in error_handler\n      return fn(*args, **kwargs)\n    File \"/root/miniconda3/lib/python3.8/site-packages/keras/engine/functional.py\", line 458, in call\n      return self._run_internal_graph(\n    File \"/root/miniconda3/lib/python3.8/site-packages/keras/engine/functional.py\", line 596, in _run_internal_graph\n      outputs = node.layer(*args, **kwargs)\n    File \"/root/miniconda3/lib/python3.8/site-packages/keras/utils/traceback_utils.py\", line 64, in error_handler\n      return fn(*args, **kwargs)\n    File \"/root/miniconda3/lib/python3.8/site-packages/keras/engine/base_layer.py\", line 1014, in __call__\n      outputs = call_fn(inputs, *args, **kwargs)\n    File \"/root/miniconda3/lib/python3.8/site-packages/keras/utils/traceback_utils.py\", line 92, in error_handler\n      return fn(*args, **kwargs)\n    File \"/root/miniconda3/lib/python3.8/site-packages/keras/layers/convolutional/base_conv.py\", line 250, in call\n      outputs = self.convolution_op(inputs, self.kernel)\n    File \"/root/miniconda3/lib/python3.8/site-packages/keras/layers/convolutional/base_conv.py\", line 225, in convolution_op\n      return tf.nn.convolution(\nNode: 'model/mobilenetv2_0.35_128/Conv1/Conv2D'\nNo algorithm worked!  Error messages:\n  Profiling failure on CUDNN engine 1#TC: UNKNOWN: CUDNN_STATUS_EXECUTION_FAILED\nin tensorflow/stream_executor/cuda/cuda_dnn.cc(4023): 'cudnnConvolutionForward( cudnn.handle(), alpha, input_nd_.handle(), input_data.opaque(), filter_.handle(), filter_data.opaque(), conv_.handle(), ToConvForwardAlgo(algo), scratch_memory.opaque(), scratch_memory.size(), beta, output_nd_.handle(), output_data.opaque())'\n  Profiling failure on CUDNN engine 1: UNKNOWN: CUDNN_STATUS_EXECUTION_FAILED\nin tensorflow/stream_executor/cuda/cuda_dnn.cc(4023): 'cudnnConvolutionForward( cudnn.handle(), alpha, input_nd_.handle(), input_data.opaque(), filter_.handle(), filter_data.opaque(), conv_.handle(), ToConvForwardAlgo(algo), scratch_memory.opaque(), scratch_memory.size(), beta, output_nd_.handle(), output_data.opaque())'\n  Profiling failure on CUDNN engine 0#TC: UNKNOWN: CUDNN_STATUS_EXECUTION_FAILED\nin tensorflow/stream_executor/cuda/cuda_dnn.cc(4023): 'cudnnConvolutionForward( cudnn.handle(), alpha, input_nd_.handle(), input_data.opaque(), filter_.handle(), filter_data.opaque(), conv_.handle(), ToConvForwardAlgo(algo), scratch_memory.opaque(), scratch_memory.size(), beta, output_nd_.handle(), output_data.opaque())'\n  Profiling failure on CUDNN engine 0: UNKNOWN: CUDNN_STATUS_EXECUTION_FAILED\nin tensorflow/stream_executor/cuda/cuda_dnn.cc(4023): 'cudnnConvolutionForward( cudnn.handle(), alpha, input_nd_.handle(), input_data.opaque(), filter_.handle(), filter_data.opaque(), conv_.handle(), ToConvForwardAlgo(algo), scratch_memory.opaque(), scratch_memory.size(), beta, output_nd_.handle(), output_data.opaque())'\n  Profiling failure on CUDNN engine 2#TC: RESOURCE_EXHAUSTED: Out of memory while trying to allocate 73400320 bytes.\n  Profiling failure on CUDNN engine 2: RESOURCE_EXHAUSTED: Out of memory while trying to allocate 73400320 bytes.\n  Profiling failure on CUDNN engine 5#TC: RESOURCE_EXHAUSTED: Out of memory while trying to allocate 38154240 bytes.\n  Profiling failure on CUDNN engine 5: RESOURCE_EXHAUSTED: Out of memory while trying to allocate 38154240 bytes.\n\t [[{{node model/mobilenetv2_0.35_128/Conv1/Conv2D}}]] [Op:__inference_train_function_79089]\n",
     "output_type": "error",
     "traceback": [
      "\u001b[0;31m---------------------------------------------------------------------------\u001b[0m",
      "\u001b[0;31mRuntimeError\u001b[0m                              Traceback (most recent call last)",
      "Input \u001b[0;32mIn [6]\u001b[0m, in \u001b[0;36m<cell line: 9>\u001b[0;34m()\u001b[0m\n\u001b[1;32m      1\u001b[0m tuner \u001b[38;5;241m=\u001b[39m keras_tuner\u001b[38;5;241m.\u001b[39mBayesianOptimization(\n\u001b[1;32m      2\u001b[0m     hypermodel \u001b[38;5;241m=\u001b[39mHyperMobilenet_v2(input_size\u001b[38;5;241m=\u001b[39m\u001b[38;5;241m128\u001b[39m,batch_size\u001b[38;5;241m=\u001b[39m\u001b[38;5;241m128\u001b[39m,train_root\u001b[38;5;241m=\u001b[39m\u001b[38;5;124m'\u001b[39m\u001b[38;5;124m/root/autodl-tmp/AllAlphaBets\u001b[39m\u001b[38;5;124m'\u001b[39m),\n\u001b[1;32m      3\u001b[0m     objective\u001b[38;5;241m=\u001b[39m\u001b[38;5;124m\"\u001b[39m\u001b[38;5;124mval_accuracy\u001b[39m\u001b[38;5;124m\"\u001b[39m,\n\u001b[0;32m   (...)\u001b[0m\n\u001b[1;32m      7\u001b[0m     project_name\u001b[38;5;241m=\u001b[39m\u001b[38;5;124m\"\u001b[39m\u001b[38;5;124mtune_hypermodel\u001b[39m\u001b[38;5;124m\"\u001b[39m,\n\u001b[1;32m      8\u001b[0m )\n\u001b[0;32m----> 9\u001b[0m \u001b[43mtuner\u001b[49m\u001b[38;5;241;43m.\u001b[39;49m\u001b[43msearch\u001b[49m\u001b[43m(\u001b[49m\u001b[43mepochs\u001b[49m\u001b[38;5;241;43m=\u001b[39;49m\u001b[38;5;241;43m10\u001b[39;49m\u001b[43m,\u001b[49m\u001b[43mworkers\u001b[49m\u001b[38;5;241;43m=\u001b[39;49m\u001b[38;5;241;43m8\u001b[39;49m\u001b[43m)\u001b[49m\n",
      "File \u001b[0;32m~/miniconda3/lib/python3.8/site-packages/keras_tuner/src/engine/base_tuner.py:235\u001b[0m, in \u001b[0;36mBaseTuner.search\u001b[0;34m(self, *fit_args, **fit_kwargs)\u001b[0m\n\u001b[1;32m    233\u001b[0m     \u001b[38;5;28mself\u001b[39m\u001b[38;5;241m.\u001b[39mon_trial_begin(trial)\n\u001b[1;32m    234\u001b[0m     \u001b[38;5;28mself\u001b[39m\u001b[38;5;241m.\u001b[39m_try_run_and_update_trial(trial, \u001b[38;5;241m*\u001b[39mfit_args, \u001b[38;5;241m*\u001b[39m\u001b[38;5;241m*\u001b[39mfit_kwargs)\n\u001b[0;32m--> 235\u001b[0m     \u001b[38;5;28;43mself\u001b[39;49m\u001b[38;5;241;43m.\u001b[39;49m\u001b[43mon_trial_end\u001b[49m\u001b[43m(\u001b[49m\u001b[43mtrial\u001b[49m\u001b[43m)\u001b[49m\n\u001b[1;32m    236\u001b[0m \u001b[38;5;28mself\u001b[39m\u001b[38;5;241m.\u001b[39mon_search_end()\n",
      "File \u001b[0;32m~/miniconda3/lib/python3.8/site-packages/keras_tuner/src/engine/base_tuner.py:339\u001b[0m, in \u001b[0;36mBaseTuner.on_trial_end\u001b[0;34m(self, trial)\u001b[0m\n\u001b[1;32m    333\u001b[0m \u001b[38;5;28;01mdef\u001b[39;00m \u001b[38;5;21mon_trial_end\u001b[39m(\u001b[38;5;28mself\u001b[39m, trial):\n\u001b[1;32m    334\u001b[0m     \u001b[38;5;124;03m\"\"\"Called at the end of a trial.\u001b[39;00m\n\u001b[1;32m    335\u001b[0m \n\u001b[1;32m    336\u001b[0m \u001b[38;5;124;03m    Args:\u001b[39;00m\n\u001b[1;32m    337\u001b[0m \u001b[38;5;124;03m        trial: A `Trial` instance.\u001b[39;00m\n\u001b[1;32m    338\u001b[0m \u001b[38;5;124;03m    \"\"\"\u001b[39;00m\n\u001b[0;32m--> 339\u001b[0m     \u001b[38;5;28;43mself\u001b[39;49m\u001b[38;5;241;43m.\u001b[39;49m\u001b[43moracle\u001b[49m\u001b[38;5;241;43m.\u001b[39;49m\u001b[43mend_trial\u001b[49m\u001b[43m(\u001b[49m\u001b[43mtrial\u001b[49m\u001b[43m)\u001b[49m\n\u001b[1;32m    340\u001b[0m     \u001b[38;5;28mself\u001b[39m\u001b[38;5;241m.\u001b[39msave()\n",
      "File \u001b[0;32m~/miniconda3/lib/python3.8/site-packages/keras_tuner/src/engine/oracle.py:108\u001b[0m, in \u001b[0;36msynchronized.<locals>.wrapped_func\u001b[0;34m(*args, **kwargs)\u001b[0m\n\u001b[1;32m    106\u001b[0m     LOCKS[oracle]\u001b[38;5;241m.\u001b[39macquire()\n\u001b[1;32m    107\u001b[0m     THREADS[oracle] \u001b[38;5;241m=\u001b[39m thread_name\n\u001b[0;32m--> 108\u001b[0m ret_val \u001b[38;5;241m=\u001b[39m \u001b[43mfunc\u001b[49m\u001b[43m(\u001b[49m\u001b[38;5;241;43m*\u001b[39;49m\u001b[43margs\u001b[49m\u001b[43m,\u001b[49m\u001b[43m \u001b[49m\u001b[38;5;241;43m*\u001b[39;49m\u001b[38;5;241;43m*\u001b[39;49m\u001b[43mkwargs\u001b[49m\u001b[43m)\u001b[49m\n\u001b[1;32m    109\u001b[0m \u001b[38;5;28;01mif\u001b[39;00m need_acquire:\n\u001b[1;32m    110\u001b[0m     THREADS[oracle] \u001b[38;5;241m=\u001b[39m \u001b[38;5;28;01mNone\u001b[39;00m\n",
      "File \u001b[0;32m~/miniconda3/lib/python3.8/site-packages/keras_tuner/src/engine/oracle.py:588\u001b[0m, in \u001b[0;36mOracle.end_trial\u001b[0;34m(self, trial)\u001b[0m\n\u001b[1;32m    586\u001b[0m \u001b[38;5;28;01mif\u001b[39;00m \u001b[38;5;129;01mnot\u001b[39;00m \u001b[38;5;28mself\u001b[39m\u001b[38;5;241m.\u001b[39m_retry(trial):\n\u001b[1;32m    587\u001b[0m     \u001b[38;5;28mself\u001b[39m\u001b[38;5;241m.\u001b[39mend_order\u001b[38;5;241m.\u001b[39mappend(trial\u001b[38;5;241m.\u001b[39mtrial_id)\n\u001b[0;32m--> 588\u001b[0m     \u001b[38;5;28;43mself\u001b[39;49m\u001b[38;5;241;43m.\u001b[39;49m\u001b[43m_check_consecutive_failures\u001b[49m\u001b[43m(\u001b[49m\u001b[43m)\u001b[49m\n\u001b[1;32m    590\u001b[0m \u001b[38;5;28mself\u001b[39m\u001b[38;5;241m.\u001b[39m_save_trial(trial)\n\u001b[1;32m    591\u001b[0m \u001b[38;5;28mself\u001b[39m\u001b[38;5;241m.\u001b[39msave()\n",
      "File \u001b[0;32m~/miniconda3/lib/python3.8/site-packages/keras_tuner/src/engine/oracle.py:545\u001b[0m, in \u001b[0;36mOracle._check_consecutive_failures\u001b[0;34m(self)\u001b[0m\n\u001b[1;32m    543\u001b[0m     consecutive_failures \u001b[38;5;241m=\u001b[39m \u001b[38;5;241m0\u001b[39m\n\u001b[1;32m    544\u001b[0m \u001b[38;5;28;01mif\u001b[39;00m consecutive_failures \u001b[38;5;241m==\u001b[39m \u001b[38;5;28mself\u001b[39m\u001b[38;5;241m.\u001b[39mmax_consecutive_failed_trials:\n\u001b[0;32m--> 545\u001b[0m     \u001b[38;5;28;01mraise\u001b[39;00m \u001b[38;5;167;01mRuntimeError\u001b[39;00m(\n\u001b[1;32m    546\u001b[0m         \u001b[38;5;124m\"\u001b[39m\u001b[38;5;124mNumber of consecutive failures exceeded the limit \u001b[39m\u001b[38;5;124m\"\u001b[39m\n\u001b[1;32m    547\u001b[0m         \u001b[38;5;124mf\u001b[39m\u001b[38;5;124m\"\u001b[39m\u001b[38;5;124mof \u001b[39m\u001b[38;5;132;01m{\u001b[39;00m\u001b[38;5;28mself\u001b[39m\u001b[38;5;241m.\u001b[39mmax_consecutive_failed_trials\u001b[38;5;132;01m}\u001b[39;00m\u001b[38;5;124m.\u001b[39m\u001b[38;5;130;01m\\n\u001b[39;00m\u001b[38;5;124m\"\u001b[39m\n\u001b[1;32m    548\u001b[0m         \u001b[38;5;241m+\u001b[39m (trial\u001b[38;5;241m.\u001b[39mmessage \u001b[38;5;129;01mor\u001b[39;00m \u001b[38;5;124m\"\u001b[39m\u001b[38;5;124m\"\u001b[39m)\n\u001b[1;32m    549\u001b[0m     )\n",
      "\u001b[0;31mRuntimeError\u001b[0m: Number of consecutive failures exceeded the limit of 3.\nTraceback (most recent call last):\n  File \"/root/miniconda3/lib/python3.8/site-packages/keras_tuner/src/engine/base_tuner.py\", line 274, in _try_run_and_update_trial\n    self._run_and_update_trial(trial, *fit_args, **fit_kwargs)\n  File \"/root/miniconda3/lib/python3.8/site-packages/keras_tuner/src/engine/base_tuner.py\", line 239, in _run_and_update_trial\n    results = self.run_trial(trial, *fit_args, **fit_kwargs)\n  File \"/root/miniconda3/lib/python3.8/site-packages/keras_tuner/src/engine/tuner.py\", line 314, in run_trial\n    obj_value = self._build_and_fit_model(trial, *args, **copied_kwargs)\n  File \"/root/miniconda3/lib/python3.8/site-packages/keras_tuner/src/engine/tuner.py\", line 233, in _build_and_fit_model\n    results = self.hypermodel.fit(hp, model, *args, **kwargs)\n  File \"/tmp/ipykernel_20631/355277094.py\", line 76, in fit\n    return model.fit(\n  File \"/root/miniconda3/lib/python3.8/site-packages/keras/utils/traceback_utils.py\", line 67, in error_handler\n    raise e.with_traceback(filtered_tb) from None\n  File \"/root/miniconda3/lib/python3.8/site-packages/tensorflow/python/eager/execute.py\", line 54, in quick_execute\n    tensors = pywrap_tfe.TFE_Py_Execute(ctx._handle, device_name, op_name,\ntensorflow.python.framework.errors_impl.NotFoundError: Graph execution error:\n\nDetected at node 'model/mobilenetv2_0.35_128/Conv1/Conv2D' defined at (most recent call last):\n    File \"/root/miniconda3/lib/python3.8/runpy.py\", line 194, in _run_module_as_main\n      return _run_code(code, main_globals, None,\n    File \"/root/miniconda3/lib/python3.8/runpy.py\", line 87, in _run_code\n      exec(code, run_globals)\n    File \"/root/miniconda3/lib/python3.8/site-packages/ipykernel_launcher.py\", line 17, in <module>\n      app.launch_new_instance()\n    File \"/root/miniconda3/lib/python3.8/site-packages/traitlets/config/application.py\", line 976, in launch_instance\n      app.start()\n    File \"/root/miniconda3/lib/python3.8/site-packages/ipykernel/kernelapp.py\", line 712, in start\n      self.io_loop.start()\n    File \"/root/miniconda3/lib/python3.8/site-packages/tornado/platform/asyncio.py\", line 199, in start\n      self.asyncio_loop.run_forever()\n    File \"/root/miniconda3/lib/python3.8/asyncio/base_events.py\", line 570, in run_forever\n      self._run_once()\n    File \"/root/miniconda3/lib/python3.8/asyncio/base_events.py\", line 1859, in _run_once\n      handle._run()\n    File \"/root/miniconda3/lib/python3.8/asyncio/events.py\", line 81, in _run\n      self._context.run(self._callback, *self._args)\n    File \"/root/miniconda3/lib/python3.8/site-packages/ipykernel/kernelbase.py\", line 510, in dispatch_queue\n      await self.process_one()\n    File \"/root/miniconda3/lib/python3.8/site-packages/ipykernel/kernelbase.py\", line 499, in process_one\n      await dispatch(*args)\n    File \"/root/miniconda3/lib/python3.8/site-packages/ipykernel/kernelbase.py\", line 406, in dispatch_shell\n      await result\n    File \"/root/miniconda3/lib/python3.8/site-packages/ipykernel/kernelbase.py\", line 730, in execute_request\n      reply_content = await reply_content\n    File \"/root/miniconda3/lib/python3.8/site-packages/ipykernel/ipkernel.py\", line 383, in do_execute\n      res = shell.run_cell(\n    File \"/root/miniconda3/lib/python3.8/site-packages/ipykernel/zmqshell.py\", line 528, in run_cell\n      return super().run_cell(*args, **kwargs)\n    File \"/root/miniconda3/lib/python3.8/site-packages/IPython/core/interactiveshell.py\", line 2880, in run_cell\n      result = self._run_cell(\n    File \"/root/miniconda3/lib/python3.8/site-packages/IPython/core/interactiveshell.py\", line 2935, in _run_cell\n      return runner(coro)\n    File \"/root/miniconda3/lib/python3.8/site-packages/IPython/core/async_helpers.py\", line 129, in _pseudo_sync_runner\n      coro.send(None)\n    File \"/root/miniconda3/lib/python3.8/site-packages/IPython/core/interactiveshell.py\", line 3134, in run_cell_async\n      has_raised = await self.run_ast_nodes(code_ast.body, cell_name,\n    File \"/root/miniconda3/lib/python3.8/site-packages/IPython/core/interactiveshell.py\", line 3337, in run_ast_nodes\n      if await self.run_code(code, result, async_=asy):\n    File \"/root/miniconda3/lib/python3.8/site-packages/IPython/core/interactiveshell.py\", line 3397, in run_code\n      exec(code_obj, self.user_global_ns, self.user_ns)\n    File \"/tmp/ipykernel_20631/2539944366.py\", line 9, in <cell line: 9>\n      tuner.search(epochs=10,workers=8)\n    File \"/root/miniconda3/lib/python3.8/site-packages/keras_tuner/src/engine/base_tuner.py\", line 234, in search\n      self._try_run_and_update_trial(trial, *fit_args, **fit_kwargs)\n    File \"/root/miniconda3/lib/python3.8/site-packages/keras_tuner/src/engine/base_tuner.py\", line 274, in _try_run_and_update_trial\n      self._run_and_update_trial(trial, *fit_args, **fit_kwargs)\n    File \"/root/miniconda3/lib/python3.8/site-packages/keras_tuner/src/engine/base_tuner.py\", line 239, in _run_and_update_trial\n      results = self.run_trial(trial, *fit_args, **fit_kwargs)\n    File \"/root/miniconda3/lib/python3.8/site-packages/keras_tuner/src/engine/tuner.py\", line 314, in run_trial\n      obj_value = self._build_and_fit_model(trial, *args, **copied_kwargs)\n    File \"/root/miniconda3/lib/python3.8/site-packages/keras_tuner/src/engine/tuner.py\", line 233, in _build_and_fit_model\n      results = self.hypermodel.fit(hp, model, *args, **kwargs)\n    File \"/tmp/ipykernel_20631/355277094.py\", line 76, in fit\n      return model.fit(\n    File \"/root/miniconda3/lib/python3.8/site-packages/keras/utils/traceback_utils.py\", line 64, in error_handler\n      return fn(*args, **kwargs)\n    File \"/root/miniconda3/lib/python3.8/site-packages/keras/engine/training.py\", line 1409, in fit\n      tmp_logs = self.train_function(iterator)\n    File \"/root/miniconda3/lib/python3.8/site-packages/keras/engine/training.py\", line 1051, in train_function\n      return step_function(self, iterator)\n    File \"/root/miniconda3/lib/python3.8/site-packages/keras/engine/training.py\", line 1040, in step_function\n      outputs = model.distribute_strategy.run(run_step, args=(data,))\n    File \"/root/miniconda3/lib/python3.8/site-packages/keras/engine/training.py\", line 1030, in run_step\n      outputs = model.train_step(data)\n    File \"/root/miniconda3/lib/python3.8/site-packages/keras/engine/training.py\", line 889, in train_step\n      y_pred = self(x, training=True)\n    File \"/root/miniconda3/lib/python3.8/site-packages/keras/utils/traceback_utils.py\", line 64, in error_handler\n      return fn(*args, **kwargs)\n    File \"/root/miniconda3/lib/python3.8/site-packages/keras/engine/training.py\", line 490, in __call__\n      return super().__call__(*args, **kwargs)\n    File \"/root/miniconda3/lib/python3.8/site-packages/keras/utils/traceback_utils.py\", line 64, in error_handler\n      return fn(*args, **kwargs)\n    File \"/root/miniconda3/lib/python3.8/site-packages/keras/engine/base_layer.py\", line 1014, in __call__\n      outputs = call_fn(inputs, *args, **kwargs)\n    File \"/root/miniconda3/lib/python3.8/site-packages/keras/utils/traceback_utils.py\", line 92, in error_handler\n      return fn(*args, **kwargs)\n    File \"/root/miniconda3/lib/python3.8/site-packages/keras/engine/functional.py\", line 458, in call\n      return self._run_internal_graph(\n    File \"/root/miniconda3/lib/python3.8/site-packages/keras/engine/functional.py\", line 596, in _run_internal_graph\n      outputs = node.layer(*args, **kwargs)\n    File \"/root/miniconda3/lib/python3.8/site-packages/keras/utils/traceback_utils.py\", line 64, in error_handler\n      return fn(*args, **kwargs)\n    File \"/root/miniconda3/lib/python3.8/site-packages/keras/engine/training.py\", line 490, in __call__\n      return super().__call__(*args, **kwargs)\n    File \"/root/miniconda3/lib/python3.8/site-packages/keras/utils/traceback_utils.py\", line 64, in error_handler\n      return fn(*args, **kwargs)\n    File \"/root/miniconda3/lib/python3.8/site-packages/keras/engine/base_layer.py\", line 1014, in __call__\n      outputs = call_fn(inputs, *args, **kwargs)\n    File \"/root/miniconda3/lib/python3.8/site-packages/keras/utils/traceback_utils.py\", line 92, in error_handler\n      return fn(*args, **kwargs)\n    File \"/root/miniconda3/lib/python3.8/site-packages/keras/engine/functional.py\", line 458, in call\n      return self._run_internal_graph(\n    File \"/root/miniconda3/lib/python3.8/site-packages/keras/engine/functional.py\", line 596, in _run_internal_graph\n      outputs = node.layer(*args, **kwargs)\n    File \"/root/miniconda3/lib/python3.8/site-packages/keras/utils/traceback_utils.py\", line 64, in error_handler\n      return fn(*args, **kwargs)\n    File \"/root/miniconda3/lib/python3.8/site-packages/keras/engine/base_layer.py\", line 1014, in __call__\n      outputs = call_fn(inputs, *args, **kwargs)\n    File \"/root/miniconda3/lib/python3.8/site-packages/keras/utils/traceback_utils.py\", line 92, in error_handler\n      return fn(*args, **kwargs)\n    File \"/root/miniconda3/lib/python3.8/site-packages/keras/layers/convolutional/base_conv.py\", line 250, in call\n      outputs = self.convolution_op(inputs, self.kernel)\n    File \"/root/miniconda3/lib/python3.8/site-packages/keras/layers/convolutional/base_conv.py\", line 225, in convolution_op\n      return tf.nn.convolution(\nNode: 'model/mobilenetv2_0.35_128/Conv1/Conv2D'\nNo algorithm worked!  Error messages:\n  Profiling failure on CUDNN engine 1#TC: UNKNOWN: CUDNN_STATUS_EXECUTION_FAILED\nin tensorflow/stream_executor/cuda/cuda_dnn.cc(4023): 'cudnnConvolutionForward( cudnn.handle(), alpha, input_nd_.handle(), input_data.opaque(), filter_.handle(), filter_data.opaque(), conv_.handle(), ToConvForwardAlgo(algo), scratch_memory.opaque(), scratch_memory.size(), beta, output_nd_.handle(), output_data.opaque())'\n  Profiling failure on CUDNN engine 1: UNKNOWN: CUDNN_STATUS_EXECUTION_FAILED\nin tensorflow/stream_executor/cuda/cuda_dnn.cc(4023): 'cudnnConvolutionForward( cudnn.handle(), alpha, input_nd_.handle(), input_data.opaque(), filter_.handle(), filter_data.opaque(), conv_.handle(), ToConvForwardAlgo(algo), scratch_memory.opaque(), scratch_memory.size(), beta, output_nd_.handle(), output_data.opaque())'\n  Profiling failure on CUDNN engine 0#TC: UNKNOWN: CUDNN_STATUS_EXECUTION_FAILED\nin tensorflow/stream_executor/cuda/cuda_dnn.cc(4023): 'cudnnConvolutionForward( cudnn.handle(), alpha, input_nd_.handle(), input_data.opaque(), filter_.handle(), filter_data.opaque(), conv_.handle(), ToConvForwardAlgo(algo), scratch_memory.opaque(), scratch_memory.size(), beta, output_nd_.handle(), output_data.opaque())'\n  Profiling failure on CUDNN engine 0: UNKNOWN: CUDNN_STATUS_EXECUTION_FAILED\nin tensorflow/stream_executor/cuda/cuda_dnn.cc(4023): 'cudnnConvolutionForward( cudnn.handle(), alpha, input_nd_.handle(), input_data.opaque(), filter_.handle(), filter_data.opaque(), conv_.handle(), ToConvForwardAlgo(algo), scratch_memory.opaque(), scratch_memory.size(), beta, output_nd_.handle(), output_data.opaque())'\n  Profiling failure on CUDNN engine 2#TC: RESOURCE_EXHAUSTED: Out of memory while trying to allocate 73400320 bytes.\n  Profiling failure on CUDNN engine 2: RESOURCE_EXHAUSTED: Out of memory while trying to allocate 73400320 bytes.\n  Profiling failure on CUDNN engine 5#TC: RESOURCE_EXHAUSTED: Out of memory while trying to allocate 38154240 bytes.\n  Profiling failure on CUDNN engine 5: RESOURCE_EXHAUSTED: Out of memory while trying to allocate 38154240 bytes.\n\t [[{{node model/mobilenetv2_0.35_128/Conv1/Conv2D}}]] [Op:__inference_train_function_79089]\n"
     ]
    }
   ],
   "source": [
    "tuner = keras_tuner.BayesianOptimization(\n",
    "    hypermodel =HyperMobilenet_v2(input_size=128,batch_size=128,train_root='/root/autodl-tmp/AllAlphaBets'),\n",
    "    objective=\"val_accuracy\",\n",
    "    max_trials=50,\n",
    "    overwrite=True,\n",
    "    directory=\"my_dir\",\n",
    "    project_name=\"tune_hypermodel\",\n",
    ")\n",
    "tuner.search(epochs=10,workers=8)"
   ]
  },
  {
   "cell_type": "code",
   "execution_count": null,
   "id": "e0eba9fa-9e20-4fb5-8064-6f6f5e6ad1d7",
   "metadata": {},
   "outputs": [],
   "source": []
  }
 ],
 "metadata": {
  "kernelspec": {
   "display_name": "Python 3 (ipykernel)",
   "language": "python",
   "name": "python3"
  },
  "language_info": {
   "codemirror_mode": {
    "name": "ipython",
    "version": 3
   },
   "file_extension": ".py",
   "mimetype": "text/x-python",
   "name": "python",
   "nbconvert_exporter": "python",
   "pygments_lexer": "ipython3",
   "version": "3.8.10"
  }
 },
 "nbformat": 4,
 "nbformat_minor": 5
}
